Trying request with the following proxy: {'https': '5.189.184.6:80', 'http': '5.189.184.6:80'}
Error Connecting: HTTPSConnectionPool(host='github.com', port=443): Max retries exceeded with url: /search?q=python+django-rest-framework+hello+AI+no&type=Repositories (Caused by ProxyError('Cannot connect to proxy.', timeout('timed out')))
Trying request with the following proxy: {'https': '35.247.232.115:3129', 'http': '35.247.232.115:3129'}
Error Connecting: HTTPSConnectionPool(host='github.com', port=443): Max retries exceeded with url: /search?q=python+django-rest-framework+hello+AI+no&type=Repositories (Caused by ConnectTimeoutError(<urllib3.connection.HTTPSConnection object at 0x7f2646275d00>, 'Connection to 35.247.232.115 timed out. (connect timeout=5)'))
Trying request with the following proxy: {'https': '116.203.139.170:8000', 'http': '116.203.139.170:8000'}
Error Connecting: HTTPSConnectionPool(host='github.com', port=443): Max retries exceeded with url: /search?q=python+django-rest-framework+hello+AI+no&type=Repositories (Caused by ProxyError('Cannot connect to proxy.', NewConnectionError('<urllib3.connection.HTTPSConnection object at 0x7f26462c37f0>: Failed to establish a new connection: [Errno 111] Connection refused')))
Trying request with the following proxy: {'https': '194.126.37.94:8080', 'http': '194.126.37.94:8080'}
Error Connecting: HTTPSConnectionPool(host='github.com', port=443): Max retries exceeded with url: /search?q=python+django-rest-framework+hello+AI+no&type=Repositories (Caused by ConnectTimeoutError(<urllib3.connection.HTTPSConnection object at 0x7f26462953a0>, 'Connection to 194.126.37.94 timed out. (connect timeout=5)'))
Trying request with the following proxy: {'https': '35.247.198.109:3129', 'http': '35.247.198.109:3129'}
Timeout Error: HTTPSConnectionPool(host='github.com', port=443): Read timed out. (read timeout=5)
Trying request with the following proxy: {'https': '8.213.128.6:443', 'http': '8.213.128.6:443'}
Error Connecting: HTTPSConnectionPool(host='github.com', port=443): Max retries exceeded with url: /search?q=python+django-rest-framework+hello+AI+no&type=Repositories (Caused by ConnectTimeoutError(<urllib3.connection.HTTPSConnection object at 0x7f26462285b0>, 'Connection to 8.213.128.6 timed out. (connect timeout=5)'))
Trying request with the following proxy: {'https': '172.104.117.89:80', 'http': '172.104.117.89:80'}
Error Connecting: HTTPSConnectionPool(host='github.com', port=443): Max retries exceeded with url: /search?q=python+django-rest-framework+hello+AI+no&type=Repositories (Caused by ConnectTimeoutError(<urllib3.connection.HTTPSConnection object at 0x7f2646228d90>, 'Connection to 172.104.117.89 timed out. (connect timeout=5)'))
Trying request with the following proxy: {'https': '13.78.125.167:8080', 'http': '13.78.125.167:8080'}
Error Connecting: HTTPSConnectionPool(host='github.com', port=443): Max retries exceeded with url: /search?q=python+django-rest-framework+hello+AI+no&type=Repositories (Caused by ConnectTimeoutError(<urllib3.connection.HTTPSConnection object at 0x7f2646275be0>, 'Connection to 13.78.125.167 timed out. (connect timeout=5)'))
Trying request with the following proxy: {'https': '43.156.100.152:80', 'http': '43.156.100.152:80'}
Error Connecting: HTTPSConnectionPool(host='github.com', port=443): Max retries exceeded with url: /search?q=python+django-rest-framework+hello+AI+no&type=Repositories (Caused by ProxyError('Cannot connect to proxy.', timeout('_ssl.c:1112: The handshake operation timed out')))
Trying request with the following proxy: {'https': '209.97.150.167:8080', 'http': '209.97.150.167:8080'}
Error Connecting: HTTPSConnectionPool(host='github.com', port=443): Max retries exceeded with url: /search?q=python+django-rest-framework+hello+AI+no&type=Repositories (Caused by ConnectTimeoutError(<urllib3.connection.HTTPSConnection object at 0x7f2646295b50>, 'Connection to 209.97.150.167 timed out. (connect timeout=5)'))
Trying request with the following proxy: {'https': '198.44.188.106:45787', 'http': '198.44.188.106:45787'}
